172.31.196.39 - - [23/Sep/2024 16:23:55] "GET /login?next=%2Freports%2F HTTP/1.1" 500 -
Traceback (most recent call last):
  File "/home/runner/CRM/.pythonlibs/lib/python3.11/site-packages/flask/app.py", line 2552, in __call__
    return self.wsgi_app(environ, start_response)
           ^^^^^^^^^^^^^^^^^^^^^^^^^^^^^^^^^^^^^^
  File "/home/runner/CRM/.pythonlibs/lib/python3.11/site-packages/flask/app.py", line 2532, in wsgi_app
    response = self.handle_exception(e)
               ^^^^^^^^^^^^^^^^^^^^^^^^
  File "/home/runner/CRM/.pythonlibs/lib/python3.11/site-packages/flask/app.py", line 2529, in wsgi_app
    response = self.full_dispatch_request()
               ^^^^^^^^^^^^^^^^^^^^^^^^^^^^
  File "/home/runner/CRM/.pythonlibs/lib/python3.11/site-packages/flask/app.py", line 1825, in full_dispatch_request
    rv = self.handle_user_exception(e)
         ^^^^^^^^^^^^^^^^^^^^^^^^^^^^^
  File "/home/runner/CRM/.pythonlibs/lib/python3.11/site-packages/flask/app.py", line 1823, in full_dispatch_request
    rv = self.dispatch_request()
         ^^^^^^^^^^^^^^^^^^^^^^^
  File "/home/runner/CRM/.pythonlibs/lib/python3.11/site-packages/flask/app.py", line 1799, in dispatch_request
    return self.ensure_sync(self.view_functions[rule.endpoint])(**view_args)
           ^^^^^^^^^^^^^^^^^^^^^^^^^^^^^^^^^^^^^^^^^^^^^^^^^^^^^^^^^^^^^^^^^
  File "/home/runner/CRM/routes/auth.py", line 27, in login
    return render_template('login.html', title='Sign In', form=form)
           ^^^^^^^^^^^^^^^^^^^^^^^^^^^^^^^^^^^^^^^^^^^^^^^^^^^^^^^^^
  File "/home/runner/CRM/.pythonlibs/lib/python3.11/site-packages/flask/templating.py", line 147, in render_template
    return _render(app, template, context)
           ^^^^^^^^^^^^^^^^^^^^^^^^^^^^^^^
  File "/home/runner/CRM/.pythonlibs/lib/python3.11/site-packages/flask/templating.py", line 130, in _render
    rv = template.render(context)
         ^^^^^^^^^^^^^^^^^^^^^^^^
  File "/home/runner/CRM/.pythonlibs/lib/python3.11/site-packages/jinja2/environment.py", line 1304, in render
    self.environment.handle_exception()
  File "/home/runner/CRM/.pythonlibs/lib/python3.11/site-packages/jinja2/environment.py", line 939, in handle_exception
    raise rewrite_traceback_stack(source=source)
  File "/home/runner/CRM/templates/login.html", line 1, in top-level template code
    {% extends "base.html" %}
  File "/home/runner/CRM/templates/base.html", line 15, in top-level template code
    <li><a href="{{ url_for('main.dashboard') }}">Dashboard</a></li>
  File "/home/runner/CRM/.pythonlibs/lib/python3.11/site-packages/flask/app.py", line 2034, in url_for
    return self.handle_url_build_error(error, endpoint, values)
           ^^^^^^^^^^^^^^^^^^^^^^^^^^^^^^^^^^^^^^^^^^^^^^^^^^^^
  File "/home/runner/CRM/.pythonlibs/lib/python3.11/site-packages/flask/app.py", line 2023, in url_for
    rv = url_adapter.build(  # type: ignore[union-attr]
         ^^^^^^^^^^^^^^^^^^^^^^^^^^^^^^^^^^^^^^^^^^^^^^
  File "/home/runner/CRM/.pythonlibs/lib/python3.11/site-packages/werkzeug/routing/map.py", line 917, in build
    raise BuildError(endpoint, values, method, self)
werkzeug.routing.exceptions.BuildError: Could not build url for endpoint 'main.dashboard'. Did you mean 'mobile.mobile_dashboard' instead?
172.31.196.39 - - [23/Sep/2024 16:23:56] "GET /login?__debugger__=yes&cmd=resource&f=style.css HTTP/1.1" 304 -