2024-09-27 11:38:52,435 INFO: IMAP4_SSL connection established with SSL version: 2 [in /home/runner/CRM/email_receiver.py:42]
2024-09-27 11:38:53,184 INFO: Successfully logged in to the email server [in /home/runner/CRM/email_receiver.py:44]
2024-09-27 11:38:53,679 INFO: Fetching emails for the last 30 minutes (from 2024-09-27 11:08:53 to 2024-09-27 11:38:53) [in /home/runner/CRM/email_receiver.py:132]
2024-09-27 11:38:54,050 INFO: Total emails found: 110 [in /home/runner/CRM/email_receiver.py:144]
2024-09-27 11:39:29,613 INFO: Processed 0 out of 110 emails [in /home/runner/CRM/email_receiver.py:221]
2024-09-27 11:46:14,510 INFO: CRM startup [in /home/runner/CRM/app.py:98]
2024-09-27 11:46:18,513 INFO: Starting scheduler [in /home/runner/CRM/app.py:121]
2024-09-27 11:46:18,515 INFO: Scheduler started [in /home/runner/CRM/app.py:123]
2024-09-27 11:46:30,840 ERROR: Exception on /login [POST] [in /home/runner/CRM/.pythonlibs/lib/python3.11/site-packages/flask/app.py:1744]
Traceback (most recent call last):
  File "/home/runner/CRM/.pythonlibs/lib/python3.11/site-packages/flask/app.py", line 2529, in wsgi_app
    response = self.full_dispatch_request()
               ^^^^^^^^^^^^^^^^^^^^^^^^^^^^
  File "/home/runner/CRM/.pythonlibs/lib/python3.11/site-packages/flask/app.py", line 1825, in full_dispatch_request
    rv = self.handle_user_exception(e)
         ^^^^^^^^^^^^^^^^^^^^^^^^^^^^^
  File "/home/runner/CRM/.pythonlibs/lib/python3.11/site-packages/flask/app.py", line 1823, in full_dispatch_request
    rv = self.dispatch_request()
         ^^^^^^^^^^^^^^^^^^^^^^^
  File "/home/runner/CRM/.pythonlibs/lib/python3.11/site-packages/flask/app.py", line 1799, in dispatch_request
    return self.ensure_sync(self.view_functions[rule.endpoint])(**view_args)
           ^^^^^^^^^^^^^^^^^^^^^^^^^^^^^^^^^^^^^^^^^^^^^^^^^^^^^^^^^^^^^^^^^
  File "/home/runner/CRM/routes/auth.py", line 19, in login
    user = User.query.filter_by(username=form.username.data).first()
           ^^^^^^^^^^^^^^^^^^^^^^^^^^^^^^^^^^^^^^^^^^^^^^^^^^^^^^^^^
  File "/home/runner/CRM/.pythonlibs/lib/python3.11/site-packages/sqlalchemy/orm/query.py", line 2728, in first
    return self.limit(1)._iter().first()  # type: ignore
           ^^^^^^^^^^^^^^^^^^^^^
  File "/home/runner/CRM/.pythonlibs/lib/python3.11/site-packages/sqlalchemy/orm/query.py", line 2827, in _iter
    result: Union[ScalarResult[_T], Result[_T]] = self.session.execute(
                                                  ^^^^^^^^^^^^^^^^^^^^^
  File "/home/runner/CRM/.pythonlibs/lib/python3.11/site-packages/sqlalchemy/orm/session.py", line 2362, in execute
    return self._execute_internal(
           ^^^^^^^^^^^^^^^^^^^^^^^
  File "/home/runner/CRM/.pythonlibs/lib/python3.11/site-packages/sqlalchemy/orm/session.py", line 2235, in _execute_internal
    bind = self.get_bind(**bind_arguments)
           ^^^^^^^^^^^^^^^^^^^^^^^^^^^^^^^
  File "/home/runner/CRM/.pythonlibs/lib/python3.11/site-packages/flask_sqlalchemy/session.py", line 61, in get_bind
    engines = self._db.engines
              ^^^^^^^^^^^^^^^^
  File "/home/runner/CRM/.pythonlibs/lib/python3.11/site-packages/flask_sqlalchemy/extension.py", line 629, in engines
    return self._app_engines[app]
           ~~~~~~~~~~~~~~~~~^^^^^
  File "/nix/store/f98g7xbckgqbkagdvpzc2r6lv3h1p9ki-python3-3.11.9/lib/python3.11/weakref.py", line 415, in __getitem__
    return self.data[ref(key)]
           ~~~~~~~~~^^^^^^^^^^
KeyError: <weakref at 0x7fabc30ea110; to 'Flask' at 0x7fabc4236450>
