2024-09-17 12:23:49,029 ERROR: Exception on /leads/1/send-follow-up [GET] [in /home/runner/CRM/.pythonlibs/lib/python3.11/site-packages/flask/app.py:838]
Traceback (most recent call last):
  File "/home/runner/CRM/.pythonlibs/lib/python3.11/site-packages/flask/app.py", line 1473, in wsgi_app
    response = self.full_dispatch_request()
               ^^^^^^^^^^^^^^^^^^^^^^^^^^^^
  File "/home/runner/CRM/.pythonlibs/lib/python3.11/site-packages/flask/app.py", line 882, in full_dispatch_request
    rv = self.handle_user_exception(e)
         ^^^^^^^^^^^^^^^^^^^^^^^^^^^^^
  File "/home/runner/CRM/.pythonlibs/lib/python3.11/site-packages/flask/app.py", line 880, in full_dispatch_request
    rv = self.dispatch_request()
         ^^^^^^^^^^^^^^^^^^^^^^^
  File "/home/runner/CRM/.pythonlibs/lib/python3.11/site-packages/flask/app.py", line 865, in dispatch_request
    return self.ensure_sync(self.view_functions[rule.endpoint])(**view_args)  # type: ignore[no-any-return]
           ^^^^^^^^^^^^^^^^^^^^^^^^^^^^^^^^^^^^^^^^^^^^^^^^^^^^^^^^^^^^^^^^^
  File "/home/runner/CRM/.pythonlibs/lib/python3.11/site-packages/flask_login/utils.py", line 290, in decorated_view
    return current_app.ensure_sync(func)(*args, **kwargs)
           ^^^^^^^^^^^^^^^^^^^^^^^^^^^^^^^^^^^^^^^^^^^^^^
  File "/home/runner/CRM/routes/leads.py", line 85, in send_individual_follow_up
    send_follow_up_email(lead)
  File "/home/runner/CRM/email_utils.py", line 41, in send_follow_up_email
    P.S. If you'd like to schedule a meeting, you can do so here: {url_for('meetings.schedule', _external=True)}
                                                                   ^^^^^^^^^^^^^^^^^^^^^^^^^^^^^^^^^^^^^^^^^^^^
  File "/home/runner/CRM/.pythonlibs/lib/python3.11/site-packages/flask/helpers.py", line 220, in url_for
    return current_app.url_for(
           ^^^^^^^^^^^^^^^^^^^^
  File "/home/runner/CRM/.pythonlibs/lib/python3.11/site-packages/flask/app.py", line 1084, in url_for
    return self.handle_url_build_error(error, endpoint, values)
           ^^^^^^^^^^^^^^^^^^^^^^^^^^^^^^^^^^^^^^^^^^^^^^^^^^^^
  File "/home/runner/CRM/.pythonlibs/lib/python3.11/site-packages/flask/app.py", line 1073, in url_for
    rv = url_adapter.build(  # type: ignore[union-attr]
         ^^^^^^^^^^^^^^^^^^^^^^^^^^^^^^^^^^^^^^^^^^^^^^
  File "/home/runner/CRM/.pythonlibs/lib/python3.11/site-packages/werkzeug/routing/map.py", line 924, in build
    raise BuildError(endpoint, values, method, self)
werkzeug.routing.exceptions.BuildError: Could not build url for endpoint 'meetings.schedule'. Did you mean 'scheduler.add_job' instead?
2024-09-17 12:24:49,271 ERROR: Exception on /accounts/ [GET] [in /home/runner/CRM/.pythonlibs/lib/python3.11/site-packages/flask/app.py:838]
Traceback (most recent call last):
  File "/home/runner/CRM/.pythonlibs/lib/python3.11/site-packages/flask/app.py", line 1473, in wsgi_app
    response = self.full_dispatch_request()
               ^^^^^^^^^^^^^^^^^^^^^^^^^^^^
  File "/home/runner/CRM/.pythonlibs/lib/python3.11/site-packages/flask/app.py", line 882, in full_dispatch_request
    rv = self.handle_user_exception(e)
         ^^^^^^^^^^^^^^^^^^^^^^^^^^^^^
  File "/home/runner/CRM/.pythonlibs/lib/python3.11/site-packages/flask/app.py", line 880, in full_dispatch_request
    rv = self.dispatch_request()
         ^^^^^^^^^^^^^^^^^^^^^^^
  File "/home/runner/CRM/.pythonlibs/lib/python3.11/site-packages/flask/app.py", line 865, in dispatch_request
    return self.ensure_sync(self.view_functions[rule.endpoint])(**view_args)  # type: ignore[no-any-return]
           ^^^^^^^^^^^^^^^^^^^^^^^^^^^^^^^^^^^^^^^^^^^^^^^^^^^^^^^^^^^^^^^^^
  File "/home/runner/CRM/.pythonlibs/lib/python3.11/site-packages/flask_login/utils.py", line 290, in decorated_view
    return current_app.ensure_sync(func)(*args, **kwargs)
           ^^^^^^^^^^^^^^^^^^^^^^^^^^^^^^^^^^^^^^^^^^^^^^
  File "/home/runner/CRM/routes/accounts.py", line 13, in list_accounts
    return render_template('accounts/list.html', accounts=accounts)
           ^^^^^^^^^^^^^^^^^^^^^^^^^^^^^^^^^^^^^^^^^^^^^^^^^^^^^^^^
  File "/home/runner/CRM/.pythonlibs/lib/python3.11/site-packages/flask/templating.py", line 149, in render_template
    template = app.jinja_env.get_or_select_template(template_name_or_list)
               ^^^^^^^^^^^^^^^^^^^^^^^^^^^^^^^^^^^^^^^^^^^^^^^^^^^^^^^^^^^
  File "/home/runner/CRM/.pythonlibs/lib/python3.11/site-packages/jinja2/environment.py", line 1084, in get_or_select_template
    return self.get_template(template_name_or_list, parent, globals)
           ^^^^^^^^^^^^^^^^^^^^^^^^^^^^^^^^^^^^^^^^^^^^^^^^^^^^^^^^^
  File "/home/runner/CRM/.pythonlibs/lib/python3.11/site-packages/jinja2/environment.py", line 1013, in get_template
    return self._load_template(name, globals)
           ^^^^^^^^^^^^^^^^^^^^^^^^^^^^^^^^^^
  File "/home/runner/CRM/.pythonlibs/lib/python3.11/site-packages/jinja2/environment.py", line 972, in _load_template
    template = self.loader.load(self, name, self.make_globals(globals))
               ^^^^^^^^^^^^^^^^^^^^^^^^^^^^^^^^^^^^^^^^^^^^^^^^^^^^^^^^
  File "/home/runner/CRM/.pythonlibs/lib/python3.11/site-packages/jinja2/loaders.py", line 126, in load
    source, filename, uptodate = self.get_source(environment, name)
                                 ^^^^^^^^^^^^^^^^^^^^^^^^^^^^^^^^^^
  File "/home/runner/CRM/.pythonlibs/lib/python3.11/site-packages/flask/templating.py", line 65, in get_source
    return self._get_source_fast(environment, template)
           ^^^^^^^^^^^^^^^^^^^^^^^^^^^^^^^^^^^^^^^^^^^^
  File "/home/runner/CRM/.pythonlibs/lib/python3.11/site-packages/flask/templating.py", line 99, in _get_source_fast
    raise TemplateNotFound(template)
jinja2.exceptions.TemplateNotFound: accounts/list.html
2024-09-17 12:24:58,472 ERROR: Exception on /reports/ [GET] [in /home/runner/CRM/.pythonlibs/lib/python3.11/site-packages/flask/app.py:838]
Traceback (most recent call last):
  File "/home/runner/CRM/.pythonlibs/lib/python3.11/site-packages/flask/app.py", line 1473, in wsgi_app
    response = self.full_dispatch_request()
               ^^^^^^^^^^^^^^^^^^^^^^^^^^^^
  File "/home/runner/CRM/.pythonlibs/lib/python3.11/site-packages/flask/app.py", line 882, in full_dispatch_request
    rv = self.handle_user_exception(e)
         ^^^^^^^^^^^^^^^^^^^^^^^^^^^^^
  File "/home/runner/CRM/.pythonlibs/lib/python3.11/site-packages/flask/app.py", line 880, in full_dispatch_request
    rv = self.dispatch_request()
         ^^^^^^^^^^^^^^^^^^^^^^^
  File "/home/runner/CRM/.pythonlibs/lib/python3.11/site-packages/flask/app.py", line 865, in dispatch_request
    return self.ensure_sync(self.view_functions[rule.endpoint])(**view_args)  # type: ignore[no-any-return]
           ^^^^^^^^^^^^^^^^^^^^^^^^^^^^^^^^^^^^^^^^^^^^^^^^^^^^^^^^^^^^^^^^^
  File "/home/runner/CRM/.pythonlibs/lib/python3.11/site-packages/flask_login/utils.py", line 290, in decorated_view
    return current_app.ensure_sync(func)(*args, **kwargs)
           ^^^^^^^^^^^^^^^^^^^^^^^^^^^^^^^^^^^^^^^^^^^^^^
  File "/home/runner/CRM/routes/reports.py", line 13, in index
    lead_status = db.session.query(Lead.status, func.count(Lead.id)).filter_by(user_id=current_user.id).group_by(Lead.status).all()
                  ^^
NameError: name 'db' is not defined
2024-09-17 14:23:45,105 INFO: CRM startup [in /home/runner/CRM/app.py:69]
2024-09-17 14:23:45,108 INFO: Starting scheduler [in /home/runner/CRM/app.py:76]
2024-09-17 14:23:45,112 INFO: Scheduler started [in /home/runner/CRM/app.py:78]
2024-09-17 14:25:01,207 INFO: CRM startup [in /home/runner/CRM/app.py:74]
2024-09-17 14:25:01,207 INFO: Starting scheduler [in /home/runner/CRM/app.py:81]
2024-09-17 14:25:01,209 INFO: Scheduler started [in /home/runner/CRM/app.py:83]
2024-09-17 14:26:12,347 INFO: CRM startup [in /home/runner/CRM/app.py:74]
2024-09-17 14:26:12,348 INFO: Starting scheduler [in /home/runner/CRM/app.py:81]
2024-09-17 14:26:12,349 INFO: Scheduler started [in /home/runner/CRM/app.py:83]
2024-09-17 14:27:19,896 INFO: CRM startup [in /home/runner/CRM/app.py:74]
2024-09-17 14:27:19,896 INFO: Starting scheduler [in /home/runner/CRM/app.py:81]
2024-09-17 14:27:19,898 INFO: Scheduler started [in /home/runner/CRM/app.py:83]
2024-09-17 14:28:44,209 INFO: CRM startup [in /home/runner/CRM/app.py:74]
2024-09-17 14:28:44,210 INFO: Starting scheduler [in /home/runner/CRM/app.py:81]
2024-09-17 14:28:44,211 INFO: Scheduler started [in /home/runner/CRM/app.py:83]
2024-09-17 14:30:19,897 INFO: Starting automated follow-ups process [in /home/runner/CRM/email_utils.py:62]
2024-09-17 14:30:19,897 INFO: Follow-up interval: 7 days [in /home/runner/CRM/email_utils.py:66]
2024-09-17 14:30:19,897 INFO: Lead score threshold: 50 [in /home/runner/CRM/email_utils.py:67]
2024-09-17 14:30:20,131 INFO: Found 0 leads that need follow-up [in /home/runner/CRM/email_utils.py:76]
2024-09-17 14:30:20,360 INFO: Successfully sent follow-up emails to 0 leads. [in /home/runner/CRM/email_utils.py:85]
2024-09-17 14:30:20,360 INFO: Completed automated follow-ups process [in /home/runner/CRM/email_utils.py:90]
2024-09-17 14:32:13,736 ERROR: Failed to send follow-up email to macnishio@gmail.com: (535, b'5.7.8 Username and Password not accepted. For more information, go to\n5.7.8  https://support.google.com/mail/?p=BadCredentials d9443c01a7336-207945da6a2sm50943145ad.57 - gsmtp') [in /home/runner/CRM/email_utils.py:59]
