2024-09-18 04:52:03,611 ERROR: Exception on /reports/ [GET] [in /home/runner/CRM/.pythonlibs/lib/python3.11/site-packages/flask/app.py:838]
Traceback (most recent call last):
  File "/home/runner/CRM/.pythonlibs/lib/python3.11/site-packages/flask/app.py", line 1473, in wsgi_app
    response = self.full_dispatch_request()
               ^^^^^^^^^^^^^^^^^^^^^^^^^^^^
  File "/home/runner/CRM/.pythonlibs/lib/python3.11/site-packages/flask/app.py", line 882, in full_dispatch_request
    rv = self.handle_user_exception(e)
         ^^^^^^^^^^^^^^^^^^^^^^^^^^^^^
  File "/home/runner/CRM/.pythonlibs/lib/python3.11/site-packages/flask/app.py", line 880, in full_dispatch_request
    rv = self.dispatch_request()
         ^^^^^^^^^^^^^^^^^^^^^^^
  File "/home/runner/CRM/.pythonlibs/lib/python3.11/site-packages/flask/app.py", line 865, in dispatch_request
    return self.ensure_sync(self.view_functions[rule.endpoint])(**view_args)  # type: ignore[no-any-return]
           ^^^^^^^^^^^^^^^^^^^^^^^^^^^^^^^^^^^^^^^^^^^^^^^^^^^^^^^^^^^^^^^^^
  File "/home/runner/CRM/.pythonlibs/lib/python3.11/site-packages/flask_login/utils.py", line 290, in decorated_view
    return current_app.ensure_sync(func)(*args, **kwargs)
           ^^^^^^^^^^^^^^^^^^^^^^^^^^^^^^^^^^^^^^^^^^^^^^
  File "/home/runner/CRM/routes/reports.py", line 13, in index
    lead_status = db.session.query(Lead.status, func.count(Lead.id)).filter_by(user_id=current_user.id).group_by(Lead.status).all()
                  ^^
NameError: name 'db' is not defined
2024-09-18 07:49:16,282 INFO: CRM startup [in /home/runner/CRM/app.py:64]
2024-09-18 07:49:16,283 INFO: Starting scheduler [in /home/runner/CRM/app.py:71]
2024-09-18 07:49:16,284 INFO: Scheduler started [in /home/runner/CRM/app.py:73]
2024-09-18 08:10:44,034 INFO: CRM startup [in /home/runner/CRM/app.py:64]
2024-09-18 08:10:44,035 INFO: Starting scheduler [in /home/runner/CRM/app.py:71]
2024-09-18 08:10:44,037 INFO: Scheduler started [in /home/runner/CRM/app.py:73]
