2024-09-25 10:56:56,220 ERROR: Exception on /leads/1 [GET] [in /home/runner/CRM/.pythonlibs/lib/python3.11/site-packages/flask/app.py:1744]
Traceback (most recent call last):
  File "/home/runner/CRM/.pythonlibs/lib/python3.11/site-packages/redis/connection.py", line 277, in connect
    sock = self.retry.call_with_retry(
           ^^^^^^^^^^^^^^^^^^^^^^^^^^^
  File "/home/runner/CRM/.pythonlibs/lib/python3.11/site-packages/redis/retry.py", line 62, in call_with_retry
    return do()
           ^^^^
  File "/home/runner/CRM/.pythonlibs/lib/python3.11/site-packages/redis/connection.py", line 278, in <lambda>
    lambda: self._connect(), lambda error: self.disconnect(error)
            ^^^^^^^^^^^^^^^
  File "/home/runner/CRM/.pythonlibs/lib/python3.11/site-packages/redis/connection.py", line 639, in _connect
    raise err
  File "/home/runner/CRM/.pythonlibs/lib/python3.11/site-packages/redis/connection.py", line 627, in _connect
    sock.connect(socket_address)
OSError: [Errno 99] Cannot assign requested address

During handling of the above exception, another exception occurred:

Traceback (most recent call last):
  File "/home/runner/CRM/.pythonlibs/lib/python3.11/site-packages/flask/app.py", line 2529, in wsgi_app
    response = self.full_dispatch_request()
               ^^^^^^^^^^^^^^^^^^^^^^^^^^^^
  File "/home/runner/CRM/.pythonlibs/lib/python3.11/site-packages/flask/app.py", line 1825, in full_dispatch_request
    rv = self.handle_user_exception(e)
         ^^^^^^^^^^^^^^^^^^^^^^^^^^^^^
  File "/home/runner/CRM/.pythonlibs/lib/python3.11/site-packages/flask/app.py", line 1821, in full_dispatch_request
    rv = self.preprocess_request()
         ^^^^^^^^^^^^^^^^^^^^^^^^^
  File "/home/runner/CRM/.pythonlibs/lib/python3.11/site-packages/flask/app.py", line 2313, in preprocess_request
    rv = self.ensure_sync(before_func)()
         ^^^^^^^^^^^^^^^^^^^^^^^^^^^^^^^
  File "/home/runner/CRM/.pythonlibs/lib/python3.11/site-packages/flask_limiter/extension.py", line 1168, in _check_request_limit
    raise e
  File "/home/runner/CRM/.pythonlibs/lib/python3.11/site-packages/flask_limiter/extension.py", line 1149, in _check_request_limit
    self.__evaluate_limits(endpoint, all_limits)
  File "/home/runner/CRM/.pythonlibs/lib/python3.11/site-packages/flask_limiter/extension.py", line 1086, in __evaluate_limits
    if not method(lim.limit, *args, **kwargs):
           ^^^^^^^^^^^^^^^^^^^^^^^^^^^^^^^^^^
  File "/home/runner/CRM/.pythonlibs/lib/python3.11/site-packages/limits/strategies.py", line 140, in hit
    self.storage.incr(
  File "/home/runner/CRM/.pythonlibs/lib/python3.11/site-packages/limits/storage/base.py", line 27, in inner
    return fn(*args, **kwargs)
           ^^^^^^^^^^^^^^^^^^^
  File "/home/runner/CRM/.pythonlibs/lib/python3.11/site-packages/limits/storage/redis.py", line 209, in incr
    return int(self.lua_incr_expire([key], [expiry, amount]))
               ^^^^^^^^^^^^^^^^^^^^^^^^^^^^^^^^^^^^^^^^^^^^^
  File "/home/runner/CRM/.pythonlibs/lib/python3.11/site-packages/redis/commands/core.py", line 6296, in __call__
    return client.evalsha(self.sha, len(keys), *args)
           ^^^^^^^^^^^^^^^^^^^^^^^^^^^^^^^^^^^^^^^^^^
  File "/home/runner/CRM/.pythonlibs/lib/python3.11/site-packages/redis/commands/core.py", line 5672, in evalsha
    return self._evalsha("EVALSHA", sha, numkeys, *keys_and_args)
           ^^^^^^^^^^^^^^^^^^^^^^^^^^^^^^^^^^^^^^^^^^^^^^^^^^^^^^
  File "/home/runner/CRM/.pythonlibs/lib/python3.11/site-packages/redis/commands/core.py", line 5656, in _evalsha
    return self.execute_command(command, sha, numkeys, *keys_and_args)
           ^^^^^^^^^^^^^^^^^^^^^^^^^^^^^^^^^^^^^^^^^^^^^^^^^^^^^^^^^^^
  File "/home/runner/CRM/.pythonlibs/lib/python3.11/site-packages/redis/client.py", line 545, in execute_command
    conn = self.connection or pool.get_connection(command_name, **options)
                              ^^^^^^^^^^^^^^^^^^^^^^^^^^^^^^^^^^^^^^^^^^^^
  File "/home/runner/CRM/.pythonlibs/lib/python3.11/site-packages/redis/connection.py", line 1074, in get_connection
    connection.connect()
  File "/home/runner/CRM/.pythonlibs/lib/python3.11/site-packages/redis/connection.py", line 283, in connect
    raise ConnectionError(self._error_message(e))
redis.exceptions.ConnectionError: Error 99 connecting to localhost:6379. Cannot assign requested address.
2024-09-25 10:57:45,777 INFO: CRM startup [in /home/runner/CRM/app.py:98]
2024-09-25 10:57:45,778 INFO: Starting scheduler [in /home/runner/CRM/app.py:115]
2024-09-25 10:57:45,779 INFO: Scheduler started [in /home/runner/CRM/app.py:117]
2024-09-25 10:58:52,333 INFO: CRM startup [in /home/runner/CRM/app.py:98]
2024-09-25 10:58:52,334 INFO: Starting scheduler [in /home/runner/CRM/app.py:115]
2024-09-25 10:58:52,335 INFO: Scheduler started [in /home/runner/CRM/app.py:117]
2024-09-25 10:59:13,727 INFO: CRM startup [in /home/runner/CRM/app.py:98]
2024-09-25 10:59:13,728 INFO: Starting scheduler [in /home/runner/CRM/app.py:115]
2024-09-25 10:59:13,730 INFO: Scheduler started [in /home/runner/CRM/app.py:117]
2024-09-25 10:59:52,042 INFO: CRM startup [in /home/runner/CRM/app.py:98]
2024-09-25 10:59:52,043 INFO: Starting scheduler [in /home/runner/CRM/app.py:115]
2024-09-25 10:59:52,044 INFO: Scheduler started [in /home/runner/CRM/app.py:117]
2024-09-25 11:00:57,794 INFO: Fetching emails from 2024-08-26 to 2024-09-25 [in /home/runner/CRM/email_receiver.py:31]
2024-09-25 11:00:58,106 INFO: Total emails fetched: 0 [in /home/runner/CRM/email_receiver.py:36]
2024-09-25 11:00:58,940 INFO: Emails from known leads: 711 [in /home/runner/CRM/email_receiver.py:68]
2024-09-25 11:00:59,193 INFO: Emails from unknown senders: 2 [in /home/runner/CRM/email_receiver.py:69]
