2024-09-27 05:15:57,920 ERROR: Exception on /leads/ [GET] [in /home/runner/CRM/.pythonlibs/lib/python3.11/site-packages/flask/app.py:1414]
Traceback (most recent call last):
  File "/home/runner/CRM/.pythonlibs/lib/python3.11/site-packages/flask/app.py", line 2190, in wsgi_app
    response = self.full_dispatch_request()
               ^^^^^^^^^^^^^^^^^^^^^^^^^^^^
  File "/home/runner/CRM/.pythonlibs/lib/python3.11/site-packages/flask/app.py", line 1486, in full_dispatch_request
    rv = self.handle_user_exception(e)
         ^^^^^^^^^^^^^^^^^^^^^^^^^^^^^
  File "/home/runner/CRM/.pythonlibs/lib/python3.11/site-packages/flask/app.py", line 1484, in full_dispatch_request
    rv = self.dispatch_request()
         ^^^^^^^^^^^^^^^^^^^^^^^
  File "/home/runner/CRM/.pythonlibs/lib/python3.11/site-packages/flask/app.py", line 1469, in dispatch_request
    return self.ensure_sync(self.view_functions[rule.endpoint])(**view_args)
           ^^^^^^^^^^^^^^^^^^^^^^^^^^^^^^^^^^^^^^^^^^^^^^^^^^^^^^^^^^^^^^^^^
  File "/home/runner/CRM/.pythonlibs/lib/python3.11/site-packages/flask_login/utils.py", line 290, in decorated_view
    return current_app.ensure_sync(func)(*args, **kwargs)
           ^^^^^^^^^^^^^^^^^^^^^^^^^^^^^^^^^^^^^^^^^^^^^^
  File "/home/runner/CRM/routes/leads.py", line 19, in list_leads
    leads = Lead.query.filter_by(user_id=current_user.id).all()
            ^^^^^^^^^^^^^^^^^^^^^^^^^^^^^^^^^^^^^^^^^^^^^^^^^^^
  File "/home/runner/CRM/.pythonlibs/lib/python3.11/site-packages/sqlalchemy/orm/query.py", line 2673, in all
    return self._iter().all()  # type: ignore
           ^^^^^^^^^^^^
  File "/home/runner/CRM/.pythonlibs/lib/python3.11/site-packages/sqlalchemy/orm/query.py", line 2827, in _iter
    result: Union[ScalarResult[_T], Result[_T]] = self.session.execute(
                                                  ^^^^^^^^^^^^^^^^^^^^^
  File "/home/runner/CRM/.pythonlibs/lib/python3.11/site-packages/sqlalchemy/orm/session.py", line 2362, in execute
    return self._execute_internal(
           ^^^^^^^^^^^^^^^^^^^^^^^
  File "/home/runner/CRM/.pythonlibs/lib/python3.11/site-packages/sqlalchemy/orm/session.py", line 2235, in _execute_internal
    bind = self.get_bind(**bind_arguments)
           ^^^^^^^^^^^^^^^^^^^^^^^^^^^^^^^
  File "/home/runner/CRM/.pythonlibs/lib/python3.11/site-packages/flask_sqlalchemy/session.py", line 53, in get_bind
    engines = self._db.engines
              ^^^^^^^^^^^^^^^^
  File "/home/runner/CRM/.pythonlibs/lib/python3.11/site-packages/flask_sqlalchemy/extension.py", line 690, in engines
    raise RuntimeError(
RuntimeError: The current Flask app is not registered with this 'SQLAlchemy' instance. Did you forget to call 'init_app', or did you create multiple 'SQLAlchemy' instances?
2024-09-27 05:20:25,642 INFO: Checking for new emails [in /home/runner/CRM/email_receiver.py:253]
2024-09-27 05:20:25,661 INFO: Attempting to connect to imap.gmail.com:993 with SSL version: 2 [in /home/runner/CRM/email_receiver.py:40]
2024-09-27 05:20:26,325 INFO: IMAP4_SSL connection established with SSL version: 2 [in /home/runner/CRM/email_receiver.py:42]
2024-09-27 05:20:27,323 INFO: Successfully logged in to the email server [in /home/runner/CRM/email_receiver.py:44]
2024-09-27 05:20:27,818 INFO: Fetching emails for the last 30 minutes (from 2024-09-27 04:50:27 to 2024-09-27 05:20:27) [in /home/runner/CRM/email_receiver.py:132]
2024-09-27 05:20:28,120 INFO: Total emails found: 97 [in /home/runner/CRM/email_receiver.py:144]
2024-09-27 05:21:42,314 INFO: Processing email - Sender: =?UTF-8?B?5qCq5byP5Lya56S+44Oe44OD44K344Ol44Oe44OI44Oq44OD44Kv44K5?=
 <info@mashmatrix.com>, Subject: 視聴予約受付中！「AppExchange ONLINE Summit 2024」, Date: 2024-09-26 23:07:30 [in /home/runner/CRM/email_receiver.py:182]
2024-09-27 05:21:42,315 ERROR: Error processing email b'83032': The current Flask app is not registered with this 'SQLAlchemy' instance. Did you forget to call 'init_app', or did you create multiple 'SQLAlchemy' instances? [in /home/runner/CRM/email_receiver.py:218]
2024-09-27 05:21:43,078 INFO: Processing email - Sender: HubSpot Japan <hubspotjapan@hubspot.com>, Subject: 【HubSpot】プレミアム機能と活用事例のご紹介, Date: 2024-09-27 01:15:13 [in /home/runner/CRM/email_receiver.py:182]
2024-09-27 05:21:43,079 ERROR: Error processing email b'83033': The current Flask app is not registered with this 'SQLAlchemy' instance. Did you forget to call 'init_app', or did you create multiple 'SQLAlchemy' instances? [in /home/runner/CRM/email_receiver.py:218]
2024-09-27 05:21:43,079 INFO: Processed 0 out of 97 emails [in /home/runner/CRM/email_receiver.py:221]
2024-09-27 05:25:25,642 INFO: Checking for new emails [in /home/runner/CRM/email_receiver.py:253]
2024-09-27 05:25:25,661 INFO: Attempting to connect to imap.gmail.com:993 with SSL version: 2 [in /home/runner/CRM/email_receiver.py:40]
2024-09-27 05:25:26,375 INFO: IMAP4_SSL connection established with SSL version: 2 [in /home/runner/CRM/email_receiver.py:42]
2024-09-27 05:25:31,040 INFO: Successfully logged in to the email server [in /home/runner/CRM/email_receiver.py:44]
2024-09-27 05:42:14,790 INFO: CRM startup [in /home/runner/CRM/app.py:98]
2024-09-27 05:43:08,849 INFO: CRM startup [in /home/runner/CRM/app.py:98]
2024-09-27 05:43:31,747 INFO: CRM startup [in /home/runner/CRM/app.py:98]
2024-09-27 05:43:49,930 INFO: CRM startup [in /home/runner/CRM/app.py:98]
2024-09-27 07:59:38,671 INFO: CRM startup [in /home/runner/CRM/app.py:98]
2024-09-27 07:59:45,411 INFO: Starting scheduler [in /home/runner/CRM/app.py:118]
2024-09-27 07:59:45,413 INFO: Scheduler started [in /home/runner/CRM/app.py:120]
2024-09-27 08:00:01,764 ERROR: Exception on /leads/ [GET] [in /home/runner/CRM/.pythonlibs/lib/python3.11/site-packages/flask/app.py:1744]
Traceback (most recent call last):
  File "/home/runner/CRM/.pythonlibs/lib/python3.11/site-packages/flask/app.py", line 2529, in wsgi_app
    response = self.full_dispatch_request()
               ^^^^^^^^^^^^^^^^^^^^^^^^^^^^
  File "/home/runner/CRM/.pythonlibs/lib/python3.11/site-packages/flask/app.py", line 1825, in full_dispatch_request
    rv = self.handle_user_exception(e)
         ^^^^^^^^^^^^^^^^^^^^^^^^^^^^^
  File "/home/runner/CRM/.pythonlibs/lib/python3.11/site-packages/flask/app.py", line 1823, in full_dispatch_request
    rv = self.dispatch_request()
         ^^^^^^^^^^^^^^^^^^^^^^^
  File "/home/runner/CRM/.pythonlibs/lib/python3.11/site-packages/flask/app.py", line 1799, in dispatch_request
    return self.ensure_sync(self.view_functions[rule.endpoint])(**view_args)
           ^^^^^^^^^^^^^^^^^^^^^^^^^^^^^^^^^^^^^^^^^^^^^^^^^^^^^^^^^^^^^^^^^
  File "/home/runner/CRM/.pythonlibs/lib/python3.11/site-packages/flask_login/utils.py", line 290, in decorated_view
    return current_app.ensure_sync(func)(*args, **kwargs)
           ^^^^^^^^^^^^^^^^^^^^^^^^^^^^^^^^^^^^^^^^^^^^^^
  File "/home/runner/CRM/routes/leads.py", line 21, in list_leads
    lead.needs_follow_up = needs_follow_up(lead)
                           ^^^^^^^^^^^^^^^^^^^^^
  File "/home/runner/CRM/email_utils.py", line 89, in needs_follow_up
    return (lead.last_contact < cutoff_date or lead.last_followup_email is None) and lead.score >= lead_score_threshold
                                               ^^^^^^^^^^^^^^^^^^^^^^^^
AttributeError: 'Lead' object has no attribute 'last_followup_email'
2024-09-27 10:11:26,623 INFO: CRM startup [in /home/runner/CRM/app.py:98]
2024-09-27 10:11:33,192 INFO: Starting scheduler [in /home/runner/CRM/app.py:118]
2024-09-27 10:11:33,193 INFO: Scheduler started [in /home/runner/CRM/app.py:120]
