2024-09-27 11:12:13,259 ERROR: Exception on /login [POST] [in /home/runner/CRM/.pythonlibs/lib/python3.11/site-packages/flask/app.py:1744]
Traceback (most recent call last):
  File "/home/runner/CRM/.pythonlibs/lib/python3.11/site-packages/flask/app.py", line 2529, in wsgi_app
    response = self.full_dispatch_request()
               ^^^^^^^^^^^^^^^^^^^^^^^^^^^^
  File "/home/runner/CRM/.pythonlibs/lib/python3.11/site-packages/flask/app.py", line 1825, in full_dispatch_request
    rv = self.handle_user_exception(e)
         ^^^^^^^^^^^^^^^^^^^^^^^^^^^^^
  File "/home/runner/CRM/.pythonlibs/lib/python3.11/site-packages/flask/app.py", line 1823, in full_dispatch_request
    rv = self.dispatch_request()
         ^^^^^^^^^^^^^^^^^^^^^^^
  File "/home/runner/CRM/.pythonlibs/lib/python3.11/site-packages/flask/app.py", line 1799, in dispatch_request
    return self.ensure_sync(self.view_functions[rule.endpoint])(**view_args)
           ^^^^^^^^^^^^^^^^^^^^^^^^^^^^^^^^^^^^^^^^^^^^^^^^^^^^^^^^^^^^^^^^^
  File "/home/runner/CRM/routes/auth.py", line 19, in login
    user = User.query.filter_by(username=form.username.data).first()
           ^^^^^^^^^^^^^^^^^^^^^^^^^^^^^^^^^^^^^^^^^^^^^^^^^^^^^^^^^
  File "/home/runner/CRM/.pythonlibs/lib/python3.11/site-packages/sqlalchemy/orm/query.py", line 2728, in first
    return self.limit(1)._iter().first()  # type: ignore
           ^^^^^^^^^^^^^^^^^^^^^
  File "/home/runner/CRM/.pythonlibs/lib/python3.11/site-packages/sqlalchemy/orm/query.py", line 2827, in _iter
    result: Union[ScalarResult[_T], Result[_T]] = self.session.execute(
                                                  ^^^^^^^^^^^^^^^^^^^^^
  File "/home/runner/CRM/.pythonlibs/lib/python3.11/site-packages/sqlalchemy/orm/session.py", line 2362, in execute
    return self._execute_internal(
           ^^^^^^^^^^^^^^^^^^^^^^^
  File "/home/runner/CRM/.pythonlibs/lib/python3.11/site-packages/sqlalchemy/orm/session.py", line 2235, in _execute_internal
    bind = self.get_bind(**bind_arguments)
           ^^^^^^^^^^^^^^^^^^^^^^^^^^^^^^^
  File "/home/runner/CRM/.pythonlibs/lib/python3.11/site-packages/flask_sqlalchemy/session.py", line 61, in get_bind
    engines = self._db.engines
              ^^^^^^^^^^^^^^^^
  File "/home/runner/CRM/.pythonlibs/lib/python3.11/site-packages/flask_sqlalchemy/extension.py", line 629, in engines
    return self._app_engines[app]
           ~~~~~~~~~~~~~~~~~^^^^^
  File "/nix/store/f98g7xbckgqbkagdvpzc2r6lv3h1p9ki-python3-3.11.9/lib/python3.11/weakref.py", line 415, in __getitem__
    return self.data[ref(key)]
           ~~~~~~~~~^^^^^^^^^^
KeyError: <weakref at 0x7f5d10755120; to 'Flask' at 0x7f5d10a17990>
2024-09-27 11:16:02,636 INFO: CRM startup [in /home/runner/CRM/app.py:97]
2024-09-27 11:16:06,212 INFO: Starting scheduler [in /home/runner/CRM/app.py:118]
2024-09-27 11:16:06,214 INFO: Scheduler started [in /home/runner/CRM/app.py:120]
2024-09-27 11:16:18,415 ERROR: Exception on /login [POST] [in /home/runner/CRM/.pythonlibs/lib/python3.11/site-packages/flask/app.py:1744]
Traceback (most recent call last):
  File "/home/runner/CRM/.pythonlibs/lib/python3.11/site-packages/flask/app.py", line 2529, in wsgi_app
    response = self.full_dispatch_request()
               ^^^^^^^^^^^^^^^^^^^^^^^^^^^^
  File "/home/runner/CRM/.pythonlibs/lib/python3.11/site-packages/flask/app.py", line 1825, in full_dispatch_request
    rv = self.handle_user_exception(e)
         ^^^^^^^^^^^^^^^^^^^^^^^^^^^^^
  File "/home/runner/CRM/.pythonlibs/lib/python3.11/site-packages/flask/app.py", line 1823, in full_dispatch_request
    rv = self.dispatch_request()
         ^^^^^^^^^^^^^^^^^^^^^^^
  File "/home/runner/CRM/.pythonlibs/lib/python3.11/site-packages/flask/app.py", line 1799, in dispatch_request
    return self.ensure_sync(self.view_functions[rule.endpoint])(**view_args)
           ^^^^^^^^^^^^^^^^^^^^^^^^^^^^^^^^^^^^^^^^^^^^^^^^^^^^^^^^^^^^^^^^^
  File "/home/runner/CRM/routes/auth.py", line 19, in login
    user = User.query.filter_by(username=form.username.data).first()
           ^^^^^^^^^^^^^^^^^^^^^^^^^^^^^^^^^^^^^^^^^^^^^^^^^^^^^^^^^
  File "/home/runner/CRM/.pythonlibs/lib/python3.11/site-packages/sqlalchemy/orm/query.py", line 2728, in first
    return self.limit(1)._iter().first()  # type: ignore
           ^^^^^^^^^^^^^^^^^^^^^
  File "/home/runner/CRM/.pythonlibs/lib/python3.11/site-packages/sqlalchemy/orm/query.py", line 2827, in _iter
    result: Union[ScalarResult[_T], Result[_T]] = self.session.execute(
                                                  ^^^^^^^^^^^^^^^^^^^^^
  File "/home/runner/CRM/.pythonlibs/lib/python3.11/site-packages/sqlalchemy/orm/session.py", line 2362, in execute
    return self._execute_internal(
           ^^^^^^^^^^^^^^^^^^^^^^^
  File "/home/runner/CRM/.pythonlibs/lib/python3.11/site-packages/sqlalchemy/orm/session.py", line 2235, in _execute_internal
    bind = self.get_bind(**bind_arguments)
           ^^^^^^^^^^^^^^^^^^^^^^^^^^^^^^^
  File "/home/runner/CRM/.pythonlibs/lib/python3.11/site-packages/flask_sqlalchemy/session.py", line 61, in get_bind
    engines = self._db.engines
              ^^^^^^^^^^^^^^^^
  File "/home/runner/CRM/.pythonlibs/lib/python3.11/site-packages/flask_sqlalchemy/extension.py", line 629, in engines
    return self._app_engines[app]
           ~~~~~~~~~~~~~~~~~^^^^^
  File "/nix/store/f98g7xbckgqbkagdvpzc2r6lv3h1p9ki-python3-3.11.9/lib/python3.11/weakref.py", line 415, in __getitem__
    return self.data[ref(key)]
           ~~~~~~~~~^^^^^^^^^^
KeyError: <weakref at 0x7fb541870400; to 'Flask' at 0x7fb54069e710>
2024-09-27 11:21:02,638 INFO: Checking for new emails [in /home/runner/CRM/email_receiver.py:253]
2024-09-27 11:21:02,664 INFO: Attempting to connect to imap.gmail.com:993 with SSL version: 2 [in /home/runner/CRM/email_receiver.py:40]
2024-09-27 11:21:03,391 INFO: IMAP4_SSL connection established with SSL version: 2 [in /home/runner/CRM/email_receiver.py:42]
2024-09-27 11:21:04,588 INFO: Successfully logged in to the email server [in /home/runner/CRM/email_receiver.py:44]
2024-09-27 11:21:05,307 INFO: Fetching emails for the last 30 minutes (from 2024-09-27 10:51:05 to 2024-09-27 11:21:05) [in /home/runner/CRM/email_receiver.py:132]
2024-09-27 11:21:05,725 INFO: Total emails found: 110 [in /home/runner/CRM/email_receiver.py:144]
2024-09-27 11:22:06,190 INFO: Processing email - Sender: =?iso-2022-jp?B?GyRCJVklLyU/ITwlVyVtJWwlOBsoQg==?= <shopmail@vector.co.jp>, Subject: 【全品特価】VectorシーズンセールAUTUMN＆9/29(日)まで【3,000円】マカフィーリブセーフ 3年版【ベクターPCショップ】, Date: 2024-09-27 20:00:45 [in /home/runner/CRM/email_receiver.py:182]
2024-09-27 11:22:06,192 ERROR: Error processing email b'83046': <weakref at 0x7fb541870400; to 'Flask' at 0x7fb54069e710> [in /home/runner/CRM/email_receiver.py:218]
2024-09-27 11:22:06,192 INFO: Processed 0 out of 110 emails [in /home/runner/CRM/email_receiver.py:221]
2024-09-27 11:33:51,795 INFO: CRM startup [in /home/runner/CRM/app.py:97]
2024-09-27 11:33:55,929 INFO: Starting scheduler [in /home/runner/CRM/app.py:120]
2024-09-27 11:33:55,930 INFO: Scheduler started [in /home/runner/CRM/app.py:122]
2024-09-27 11:34:18,491 ERROR: Exception on /login [POST] [in /home/runner/CRM/.pythonlibs/lib/python3.11/site-packages/flask/app.py:1744]
Traceback (most recent call last):
  File "/home/runner/CRM/.pythonlibs/lib/python3.11/site-packages/flask/app.py", line 2529, in wsgi_app
    response = self.full_dispatch_request()
               ^^^^^^^^^^^^^^^^^^^^^^^^^^^^
  File "/home/runner/CRM/.pythonlibs/lib/python3.11/site-packages/flask/app.py", line 1825, in full_dispatch_request
    rv = self.handle_user_exception(e)
         ^^^^^^^^^^^^^^^^^^^^^^^^^^^^^
  File "/home/runner/CRM/.pythonlibs/lib/python3.11/site-packages/flask/app.py", line 1823, in full_dispatch_request
    rv = self.dispatch_request()
         ^^^^^^^^^^^^^^^^^^^^^^^
  File "/home/runner/CRM/.pythonlibs/lib/python3.11/site-packages/flask/app.py", line 1799, in dispatch_request
    return self.ensure_sync(self.view_functions[rule.endpoint])(**view_args)
           ^^^^^^^^^^^^^^^^^^^^^^^^^^^^^^^^^^^^^^^^^^^^^^^^^^^^^^^^^^^^^^^^^
  File "/home/runner/CRM/routes/auth.py", line 19, in login
    user = User.query.filter_by(username=form.username.data).first()
           ^^^^^^^^^^^^^^^^^^^^^^^^^^^^^^^^^^^^^^^^^^^^^^^^^^^^^^^^^
  File "/home/runner/CRM/.pythonlibs/lib/python3.11/site-packages/sqlalchemy/orm/query.py", line 2728, in first
    return self.limit(1)._iter().first()  # type: ignore
           ^^^^^^^^^^^^^^^^^^^^^
  File "/home/runner/CRM/.pythonlibs/lib/python3.11/site-packages/sqlalchemy/orm/query.py", line 2827, in _iter
    result: Union[ScalarResult[_T], Result[_T]] = self.session.execute(
                                                  ^^^^^^^^^^^^^^^^^^^^^
  File "/home/runner/CRM/.pythonlibs/lib/python3.11/site-packages/sqlalchemy/orm/session.py", line 2362, in execute
    return self._execute_internal(
           ^^^^^^^^^^^^^^^^^^^^^^^
  File "/home/runner/CRM/.pythonlibs/lib/python3.11/site-packages/sqlalchemy/orm/session.py", line 2235, in _execute_internal
    bind = self.get_bind(**bind_arguments)
           ^^^^^^^^^^^^^^^^^^^^^^^^^^^^^^^
  File "/home/runner/CRM/.pythonlibs/lib/python3.11/site-packages/flask_sqlalchemy/session.py", line 61, in get_bind
    engines = self._db.engines
              ^^^^^^^^^^^^^^^^
  File "/home/runner/CRM/.pythonlibs/lib/python3.11/site-packages/flask_sqlalchemy/extension.py", line 629, in engines
    return self._app_engines[app]
           ~~~~~~~~~~~~~~~~~^^^^^
  File "/nix/store/f98g7xbckgqbkagdvpzc2r6lv3h1p9ki-python3-3.11.9/lib/python3.11/weakref.py", line 415, in __getitem__
    return self.data[ref(key)]
           ~~~~~~~~~^^^^^^^^^^
KeyError: <weakref at 0x7f2957f24720; to 'Flask' at 0x7f2958ed7610>
2024-09-27 11:38:51,795 INFO: Checking for new emails [in /home/runner/CRM/email_receiver.py:253]
2024-09-27 11:38:51,815 INFO: Attempting to connect to imap.gmail.com:993 with SSL version: 2 [in /home/runner/CRM/email_receiver.py:40]
